Workbook

Sheet README
B2: CRM Sales Pipeline — Analysis Working Paper
B3: Supporting analysis for the Power BI executive dashboard designed for Sales Managers.
B5: Dataset
B6: Rows / columns | C6: 3,000 / 17
B7: Duplicates | C7: 0
B8: Lead acquisition | C8: Jan – May 2024 (all 3,000 rows)
B9: Actual close | C9: Jan – Sep 2024 (348 rows — only Customer / Churned Customer ever close)
B10: Expected close | C10: Jan 2024 – May 2025 (forecast field, not an actual)
B11: Structural nulls | C11: Stage 2,133 (71.1%) · Actual Close Date 2,652 (88.4%) — left blank, not imputed
B13: Cleaning (Power Query)
B14: • Latitude / Longitude converted from text to decimal; 'Lattitude' header typo corrected
B15: • Text columns trimmed, non-printable characters removed
B16: • 3 Industry labels fixed — typo, missing '&', double space
B17: • Probability rescaled from 0–100 to 0–1
B18: • 2 fully blank trailing columns dropped
B19: • No duplicates removed and no values imputed — structural nulls remain blank by design.
B21: Business rules
B22: • Stage is populated only when Status = Opportunity (validated: 0 rule violations).
B23: • Converted customers include both Customer and Churned Customer statuses. A customer who later churns is still counted as a successful conversion before entering churn.
B24: • Win Rate = (Customer + Churned Customer + Won) ÷ (Customer + Churned Customer + Won + Lost). Disqualified leads are excluded because they represent qualification outcomes rather than sales execution.
B25: • Churn Rate = Churned / (Customer + Churned) — attrition inside the converted base only.
... B34: Raw_Data → Power Query → Cleaned_Data → EDA_Pipeline → EDA_Segments → KPI_Planning → Power BI

Sheet Raw_Data
A1: Organization | B1: Country | C1: Lattitude | D1: Longitude | E1: Industry | F1: Organization size | G1: Owner | H1: Lead acquisition date | I1: Product | J1: Status | K1: Status sequence | L1: Stage | M1: Stage sequence | N1: Deal Value, $ | O1: Probability, % | P1: Expected close date | Q1: Actual close date
A2: Thoughtblab | B2: Netherlands | C2: 52.370216 | D2: 4.895168 | E2: Banking and Finance | F2: Small (11-200) | G2: John Smith | H2: 45402 | I2: SAAS | J2: Churned Customer | K2: 7 | N2: 833 | O2: 90 | P2: 45511 | Q2: 45470
A3: Jaxnation | B3: Spain | C3: 40.416775 | D3: -3.703790 | E3: Energy & Utilities | F3: Small (11-200) | G3: Emily Johnson | H3: 45440 | I3: SAAS | J3: Churned Customer | K3: 7 | N3: 1623 | O3: 30 | P3: 45590 | Q3: 45546
A4: Mybuzz | B4: Italy | C4: 41.902782 | D4: 12.496366 | E4: Education & Science | F4: Small (11-200) | G4: Michael Brown | H4: 45368 | I4: SAAS | J4: Churned Customer | K4: 7 | N4: 1928 | O4: 20 | P4: 45733 | Q4: 45423
A5: Kare | B5: Germany | C5: 52.520008 | D5: 13.404954 | E5: Government Administration Healthcare | F5: Small (11-200) | G5: Michael Brown | H5: 45309 | I5: SAAS | J5: Churned Customer | K5: 7 | N5: 303 | O5: 50 | P5: 45511 | Q5: 45418
A6: Skaboo | B6: Germany | C6: 52.520008 | D6: 13.404954 | E6: Energy & Utilities | F6: Small (11-200) | G6: Michael Brown | H6: 45388 | I6: SAAS | J6: Churned Customer | K6: 7 | N6: 1911 | O6: 30 | P6: 45576 | Q6: 45498
A7: Flashset | B7: Germany | C7: 52.520008 | D7: 13.404954 | E7: Transportation & Logistics | F7: Small (11-200) | G7: Laura Thompson | H7: 45343 | I7: Custom solution | J7: Churned Customer | K7: 7 | N7: 455 | O7: 20 | P7: 45558 | Q7: 45423
A8: Yozio | B8: Belgium | C8: 51.260197 | D8: 4.402771 | E8: IT & IT Services | F8: Small (11-200) | G8: Laura Thompson | H8: 45335 | I8: SAAS | J8: Churned Customer | K8: 7 | N8: 351 | O8: 30 | P8: 45369 | Q8: 45399
A9: Tanoodle | B9: Switzerland | C9: 46.204391 | D9: 6.143158 | E9: IT & IT Services | F9: Small (11-200) | G9: Jessica Martinez | H9: 45306 | I9: Custom solution | J9: Churned Customer | K9: 7 | N9: 230 | O9: 70 | P9: 45429 | Q9: 45423
A10: Reilly, Wisozk and Stamm | B10: France | C10: 48.864716 | D10: 2.349014 | E10: Retail & Distribution | F10: Small (11-200) | G10: Michael Brown | H10: 45360 | I10: SAAS | J10: Churned Customer | K10: 7 | N10: 1697 | O10: 80 | P10: 45498 | Q10: 45473
A11: O'Conner-Sawayn | B11: Switzerland | C11: 46.204391 | D11: 6.143158 | E11: Transportation & Logistics | F11: Small (11-200) | G11: Laura Thompson | H11: 45383 | I11: Services | J11: Churned Customer | K11: 7 | N11: 320 | O11: 60 | P11: 45436 | Q11: 45474
A12: Klocko-Sporer | B12: Germany | C12: 52.520008 | D12: 13.404954 | E12: Agriculture & Mining | F12: Small (11-200) | G12: Emily Johnson | H12: 45334 | I12: Custom solution | J12: Churned Customer | K12: 7 | N12: 721 | O12: 20 | P12: 45667 | Q12: 45382
A13: Borer Inc | B13: Italy | C13: 41.902782 | D13: 12.496366 | E13: Transportation & Logistics | F13: Small (11-200) | G13: Michael Brown | H13: 45351 | I13: Services | J13: Churned Customer | K13: 7 | N13: 768 | O13: 80 | P13: 45522 | Q13: 45458
... A349: Nitzsche-Cartwright | B349: Austria | C349: 48.210033 | D349: 16.363449 | E349: Government Administration Healthcare | F349: Enterprise (1001+) | G349: John Smith | H349: 45370 | I349: Custom solution | J349: Customer | K349: 6 | N349: 6762 | O349: 100 | P349: 45485 | Q349: 45425
A350: Kanoodle | B350: Switzerland | C350: 46.204391 | D350: 6.143158 | E350: Transportation & Logistics | F350: Small (11-200) | G350: David Wilson | H350: 45322 | I350: Services | J350: Disqualified | K350: 3 | N350: 1214 | O350: 60 | P350: 45668
A351: Youbridge | B351: Italy | C351: 41.902782 | D351: 12.496366 | E351: Manufacturing & Production | F351: Small (11-200) | G351: Sarah Davis | H351: 45417 | I351: Services | J351: Disqualified | K351: 3 | N351: 1916 | O351: 20 | P351: 45729
A352: Jabbercube | B352: Portugal | C352: 38.736946 | D352: -9.142685 | E352: Banking and Finance | F352: Small (11-200) | G352: Laura Thompson | H352: 45442 | I352: Services | J352: Disqualified | K352: 3 | N352: 1918 | O352: 20 | P352: 45752
A353: Dabfeed | B353: Belgium | C353: 51.260197 | D353: 4.402771 | E353: Recreation & Sports | F353: Small (11-200) | G353: Emily Johnson | H353: 45407 | I353: Services | J353: Disqualified | K353: 3 | N353: 685 | O353: 60 | P353: 45743
A354: Skiba | B354: Switzerland | C354: 46.204391 | D354: 6.143158 | E354: Banking and Finance | F354: Small (11-200) | G354: John Smith | H354: 45364 | I354: Services | J354: Disqualified | K354: 3 | N354: 315 | O354: 40 | P354: 45636
A355: Voonyx | B355: Italy | C355: 41.902782 | D355: 12.496366 | E355: Banking and Finance | F355: Small (11-200) | G355: David Wilson | H355: 45294 | I355: Custom solution | J355: Disqualified | K355: 3 | N355: 810 | O355: 50 | P355: 45370
A356: Harber and Sons | B356: Italy | C356: 41.902782 | D356: 12.496366 | E356: IT & IT Services | F356: Small (11-200) | G356: Laura Thompson | H356: 45344 | I356: SAAS | J356: Disqualified | K356: 3 | N356: 717 | O356: 70 | P356: 45402
A357: Gorczany-Hayes | B357: Netherlands | C357: 52.370216 | D357: 4.895168 | E357: Energy & Utilities | F357: Small (11-200) | G357: Sarah Davis | H357: 45403 | I357: Services | J357: Disqualified | K357: 3 | N357: 1789 | O357: 20 | P357: 45467
A358: Ritchie Inc | B358: France | C358: 48.864716 | D358: 2.349014 | E358: Construction & Engineering | F358: Small (11-200) | G358: Michael Brown | H358: 45351 | I358: SAAS | J358: Disqualified | K358: 3 | N358: 1311 | O358: 30 | P358: 45578
A359: Strosin-Romaguera | B359: Portugal | C359: 38.736946 | D359: -9.142685 | E359: Recreation & Sports | F359: Small (11-200) | G359: Laura Thompson | H359: 45429 | I359: Services | J359: Disqualified | K359: 3 | N359: 1025 | O359: 20 | P359: 45463
A360: Wyman-Homenick | B360: Germany | C360: 52.520008 | D360: 13.404954 | E360: IT & IT Services | F360: Small (11-200) | G360: Jessica Martinez | H360: 45370 | I360: SAAS | J360: Disqualified | K360: 3 | N360: 1330 | O360: 30 | P360: 45549
A361: Koelpin, Gulgowski and Boyle | B361: Italy | C361: 41.902782 | D361: 12.496366 | E361: Recreation & Sports | F361: Small (11-200) | G361: Michael Brown | H361: 45442 | I361: Services | J361: Disqualified | K361: 3 | N361: 924 | O361: 20 | P361: 45751
... A1039: Harris and Sons | B1039: France | C1039: 48.864716 | D1039: 2.349014 | E1039: IT & IT Services | F1039: Enterprise (1001+) | G1039: Michael Brown | H1039: 45351 | I1039: Services | J1039: New | K1039: 1 | N1039: 14666 | O1039: 60 | P1039: 45564
A1040: Flipopia | B1040: Belgium | C1040: 51.260197 | D1040: 4.402771 | E1040: Education & Science | F1040: Small (11-200) | G1040: Jessica Martinez | H1040: 45366 | I1040: Services | J1040: Opportunity | K1040: 5 | L1040: Initial contact | M1040: 2 | N1040: 1136 | O1040: 90 | P1040: 45388
A1041: Abata | B1041: Germany | C1041: 52.520008 | D1041: 13.404954 | E1041: Banking and Finance | F1041: Small (11-200) | G1041: Sarah Davis | H1041: 45379 | I1041: SAAS | J1041: Opportunity | K1041: 5 | L1041: Initial contact | M1041: 2 | N1041: 402 | O1041: 20 | P1041: 45644
A1042: Ntags | B1042: France | C1042: 48.864716 | D1042: 2.349014 | E1042: Energy & Utilities | F1042: Small (11-200) | G1042: Jessica Martinez | H1042: 45350 | I1042: Custom solution | J1042: Opportunity | K1042: 5 | L1042: Initial contact | M1042: 2 | N1042: 1210 | O1042: 30 | P1042: 45624
A1043: Skippad | B1043: Italy | C1043: 41.902782 | D1043: 12.496366 | E1043: Transportation & Logistics | F1043: Small (11-200) | G1043: Kevin Anderson | H1043: 45415 | I1043: Services | J1043: Opportunity | K1043: 5 | L1043: Initial contact | M1043: 2 | N1043: 1626 | O1043: 40 | P1043: 45568
A1044: Aivee | B1044: Switzerland | C1044: 46.204391 | D1044: 6.143158 | E1044: Transportation & Logistics | F1044: Small (11-200) | G1044: John Smith | H1044: 45295 | I1044: Services | J1044: Opportunity | K1044: 5 | L1044: Initial contact | M1044: 2 | N1044: 785 | O1044: 60 | P1044: 45343
A1045: Youspan | B1045: France | C1045: 48.864716 | D1045: 2.349014 | E1045: Entertainment & Media & Hospitality | F1045: Small (11-200) | G1045: Laura Thompson | H1045: 45299 | I1045: Services | J1045: Opportunity | K1045: 5 | L1045: Initial contact | M1045: 2 | N1045: 1380 | O1045: 30 | P1045: 45641
A1046: Realfire | B1046: Spain | C1046: 40.416775 | D1046: -3.703790 | E1046: Retail & Distribution | F1046: Small (11-200) | G1046: Jessica Martinez | H1046: 45415 | I1046: Services | J1046: Opportunity | K1046: 5 | L1046: Initial contact | M1046: 2 | N1046: 1885 | O1046: 70 | P1046: 45580
A1047: Quinu | B1047: Switzerland | C1047: 46.204391 | D1047: 6.143158 | E1047: IT & IT Services | F1047: Small (11-200) | G1047: Laura Thompson | H1047: 45320 | I1047: Services | J1047: Opportunity | K1047: 5 | L1047: Initial contact | M1047: 2 | N1047: 1320 | O1047: 70 | P1047: 45342
A1048: Devpulse | B1048: Portugal | C1048: 38.736946 | D1048: -9.142685 | E1048: Transportation & Logistics | F1048: Small (11-200) | G1048: Michael Brown | H1048: 45354 | I1048: Services | J1048: Opportunity | K1048: 5 | L1048: Initial contact | M1048: 2 | N1048: 683 | O1048: 100 | P1048: 45625
A1049: Skiptube | B1049: Switzerland | C1049: 46.204391 | D1049: 6.143158 | E1049: Transportation & Logistics | F1049: Small (11-200) | G1049: Laura Thompson | H1049: 45375 | I1049: Services | J1049: Opportunity | K1049: 5 | L1049: Initial contact | M1049: 2 | N1049: 909 | O1049: 40 | P1049: 45411
A1050: Skyndu | B1050: Germany | C1050: 52.520008 | D1050: 13.404954 | E1050: Banking and Finance | F1050: Small (11-200) | G1050: Jessica Martinez | H1050: 45315 | I1050: SAAS | J1050: Opportunity | K1050: 5 | L1050: Initial contact | M1050: 2 | N1050: 673 | O1050: 60 | P1050: 45647
A1051: Steuber-Lowe | B1051: Belgium | C1051: 51.260197 | D1051: 4.402771 | E1051: Government Administration Healthcare | F1051: Small (11-200) | G1051: John Smith | H1051: 45388 | I1051: Custom solution | J1051: Opportunity | K1051: 5 | L1051: Initial contact | M1051: 2 | N1051: 1498 | O1051: 60 | P1051: 45496
... A1906: Wunsch Group | B1906: Germany | C1906: 52.520008 | D1906: 13.404954 | E1906: Banking and Finance | F1906: Enterprise (1001+) | G1906: Michael Brown | H1906: 45332 | I1906: Custom solution | J1906: Opportunity | K1906: 5 | L1906: Won | M1906: 5 | N1906: 5433 | O1906: 30 | P1906: 45414
...

Sheet Cleaned_Data
A1: Organization | B1: Country | C1: Latitude | D1: Longitude | E1: Industry | F1: Organization Size | G1: Owner | H1: Lead Acquisition Date | I1: Product | J1: Status | K1: Status Sequence | L1: Stage | M1: Stage Sequence | N1: Deal Value | O1: Probability | P1: Expected Close Date | Q1: Actual Close Date
A2: Thoughtblab | B2: Netherlands | C2: 52.370216 | D2: 4.895168 | E2: Banking & Finance | F2: Small (11-200) | G2: John Smith | H2: 45402 | I2: SAAS | J2: Churned Customer | K2: 7 | N2: 833 | O2: 0.9 | P2: 45511 | Q2: 45470
A3: Jaxnation | B3: Spain | C3: 40.416775 | D3: -3.70379 | E3: Energy & Utilities | F3: Small (11-200) | G3: Emily Johnson | H3: 45440 | I3: SAAS | J3: Churned Customer | K3: 7 | N3: 1623 | O3: 0.3 | P3: 45590 | Q3: 45546
A4: Mybuzz | B4: Italy | C4: 41.902782 | D4: 12.496366 | E4: Education & Science | F4: Small (11-200) | G4: Michael Brown | H4: 45368 | I4: SAAS | J4: Churned Customer | K4: 7 | N4: 1928 | O4: 0.2 | P4: 45733 | Q4: 45423
A5: Kare | B5: Germany | C5: 52.520008 | D5: 13.404954 | E5: Government Administration & Healthcare | F5: Small (11-200) | G5: Michael Brown | H5: 45309 | I5: SAAS | J5: Churned Customer | K5: 7 | N5: 303 | O5: 0.5 | P5: 45511 | Q5: 45418
A6: Skaboo | B6: Germany | C6: 52.520008 | D6: 13.404954 | E6: Energy & Utilities | F6: Small (11-200) | G6: Michael Brown | H6: 45388 | I6: SAAS | J6: Churned Customer | K6: 7 | N6: 1911 | O6: 0.3 | P6: 45576 | Q6: 45498
A7: Flashset | B7: Germany | C7: 52.520008 | D7: 13.404954 | E7: Transportation & Logistics | F7: Small (11-200) | G7: Laura Thompson | H7: 45343 | I7: Custom solution | J7: Churned Customer | K7: 7 | N7: 455 | O7: 0.2 | P7: 45558 | Q7: 45423
A8: Yozio | B8: Belgium | C8: 51.260197 | D8: 4.402771 | E8: IT & IT Services | F8: Small (11-200) | G8: Laura Thompson | H8: 45335 | I8: SAAS | J8: Churned Customer | K8: 7 | N8: 351 | O8: 0.3 | P8: 45369 | Q8: 45399
A9: Tanoodle | B9: Switzerland | C9: 46.204391 | D9: 6.143158 | E9: IT & IT Services | F9: Small (11-200) | G9: Jessica Martinez | H9: 45306 | I9: Custom solution | J9: Churned Customer | K9: 7 | N9: 230 | O9: 0.7 | P9: 45429 | Q9: 45423
A10: Reilly, Wisozk and Stamm | B10: France | C10: 48.864716 | D10: 2.349014 | E10: Retail & Distribution | F10: Small (11-200) | G10: Michael Brown | H10: 45360 | I10: SAAS | J10: Churned Customer | K10: 7 | N10: 1697 | O10: 0.8 | P10: 45498 | Q10: 45473
A11: O'Conner-Sawayn | B11: Switzerland | C11: 46.204391 | D11: 6.143158 | E11: Transportation & Logistics | F11: Small (11-200) | G11: Laura Thompson | H11: 45383 | I11: Services | J11: Churned Customer | K11: 7 | N11: 320 | O11: 0.6 | P11: 45436 | Q11: 45474
A12: Klocko-Sporer | B12: Germany | C12: 52.520008 | D12: 13.404954 | E12: Agriculture & Mining | F12: Small (11-200) | G12: Emily Johnson | H12: 45334 | I12: Custom solution | J12: Churned Customer | K12: 7 | N12: 721 | O12: 0.2 | P12: 45667 | Q12: 45382
A13: Borer Inc | B13: Italy | C13: 41.902782 | D13: 12.496366 | E13: Transportation & Logistics | F13: Small (11-200) | G13: Michael Brown | H13: 45351 | I13: Services | J13: Churned Customer | K13: 7 | N13: 768 | O13: 0.8 | P13: 45522 | Q13: 45458
... A349: Nitzsche-Cartwright | B349: Austria | C349: 48.210033 | D349: 16.363449 | E349: Government Administration & Healthcare | F349: Enterprise (1001+) | G349: John Smith | H349: 45370 | I349: Custom solution | J349: Customer | K349: 6 | N349: 6762 | O349: 1 | P349: 45485 | Q349: 45425
A350: Kanoodle | B350: Switzerland | C350: 46.204391 | D350: 6.143158 | E350: Transportation & Logistics | F350: Small (11-200) | G350: David Wilson | H350: 45322 | I350: Services | J350: Disqualified | K350: 3 | N350: 1214 | O350: 0.6 | P350: 45668
A351: Youbridge | B351: Italy | C351: 41.902782 | D351: 12.496366 | E351: Manufacturing & Production | F351: Small (11-200) | G351: Sarah Davis | H351: 45417 | I351: Services | J351: Disqualified | K351: 3 | N351: 1916 | O351: 0.2 | P351: 45729
A352: Jabbercube | B352: Portugal | C352: 38.736946 | D352: -9.142685 | E352: Banking & Finance | F352: Small (11-200) | G352: Laura Thompson | H352: 45442 | I352: Services | J352: Disqualified | K352: 3 | N352: 1918 | O352: 0.2 | P352: 45752
A353: Dabfeed | B353: Belgium | C353: 51.260197 | D353: 4.402771 | E353: Recreation & Sports | F353: Small (11-200) | G353: Emily Johnson | H353: 45407 | I353: Services | J353: Disqualified | K353: 3 | N353: 685 | O353: 0.6 | P353: 45743
A354: Skiba | B354: Switzerland | C354: 46.204391 | D354: 6.143158 | E354: Banking & Finance | F354: Small (11-200) | G354: John Smith | H354: 45364 | I354: Services | J354: Disqualified | K354: 3 | N354: 315 | O354: 0.4 | P354: 45636
A355: Voonyx | B355: Italy | C355: 41.902782 | D355: 12.496366 | E355: Banking & Finance | F355: Small (11-200) | G355: David Wilson | H355: 45294 | I355: Custom solution | J355: Disqualified | K355: 3 | N355: 810 | O355: 0.5 | P355: 45370
A356: Harber and Sons | B356: Italy | C356: 41.902782 | D356: 12.496366 | E356: IT & IT Services | F356: Small (11-200) | G356: Laura Thompson | H356: 45344 | I356: SAAS | J356: Disqualified | K356: 3 | N356: 717 | O356: 0.7 | P356: 45402
A357: Gorczany-Hayes | B357: Netherlands | C357: 52.370216 | D357: 4.895168 | E357: Energy & Utilities | F357: Small (11-200) | G357: Sarah Davis | H357: 45403 | I357: Services | J357: Disqualified | K357: 3 | N357: 1789 | O357: 0.2 | P357: 45467
A358: Ritchie Inc | B358: France | C358: 48.864716 | D358: 2.349014 | E358: Construction & Engineering | F358: Small (11-200) | G358: Michael Brown | H358: 45351 | I358: SAAS | J358: Disqualified | K358: 3 | N358: 1311 | O358: 0.3 | P358: 45578
A359: Strosin-Romaguera | B359: Portugal | C359: 38.736946 | D359: -9.142685 | E359: Recreation & Sports | F359: Small (11-200) | G359: Laura Thompson | H359: 45429 | I359: Services | J359: Disqualified | K359: 3 | N359: 1025 | O359: 0.2 | P359: 45463
A360: Wyman-Homenick | B360: Germany | C360: 52.520008 | D360: 13.404954 | E360: IT & IT Services | F360: Small (11-200) | G360: Jessica Martinez | H360: 45370 | I360: SAAS | J360: Disqualified | K360: 3 | N360: 1330 | O360: 0.3 | P360: 45549
A361: Koelpin, Gulgowski and Boyle | B361: Italy | C361: 41.902782 | D361: 12.496366 | E361: Recreation & Sports | F361: Small (11-200) | G361: Michael Brown | H361: 45442 | I361: Services | J361: Disqualified | K361: 3 | N361: 924 | O361: 0.2 | P361: 45751
... A1039: Harris and Sons | B1039: France | C1039: 48.864716 | D1039: 2.349014 | E1039: IT & IT Services | F1039: Enterprise (1001+) | G1039: Michael Brown | H1039: 45351 | I1039: Services | J1039: New | K1039: 1 | N1039: 14666 | O1039: 0.6 | P1039: 45564
A1040: Flipopia | B1040: Belgium | C1040: 51.260197 | D1040: 4.402771 | E1040: Education & Science | F1040: Small (11-200) | G1040: Jessica Martinez | H1040: 45366 | I1040: Services | J1040: Opportunity | K1040: 5 | L1040: Initial contact | M1040: 2 | N1040: 1136 | O1040: 0.9 | P1040: 45388
A1041: Abata | B1041: Germany | C1041: 52.520008 | D1041: 13.404954 | E1041: Banking & Finance | F1041: Small (11-200) | G1041: Sarah Davis | H1041: 45379 | I1041: SAAS | J1041: Opportunity | K1041: 5 | L1041: Initial contact | M1041: 2 | N1041: 402 | O1041: 0.2 | P1041: 45644
A1042: Ntags | B1042: France | C1042: 48.864716 | D1042: 2.349014 | E1042: Energy & Utilities | F1042: Small (11-200) | G1042: Jessica Martinez | H1042: 45350 | I1042: Custom solution | J1042: Opportunity | K1042: 5 | L1042: Initial contact | M1042: 2 | N1042: 1210 | O1042: 0.3 | P1042: 45624
A1043: Skippad | B1043: Italy | C1043: 41.902782 | D1043: 12.496366 | E1043: Transportation & Logistics | F1043: Small (11-200) | G1043: Kevin Anderson | H1043: 45415 | I1043: Services | J1043: Opportunity | K1043: 5 | L1043: Initial contact | M1043: 2 | N1043: 1626 | O1043: 0.4 | P1043: 45568
A1044: Aivee | B1044: Switzerland | C1044: 46.204391 | D1044: 6.143158 | E1044: Transportation & Logistics | F1044: Small (11-200) | G1044: John Smith | H1044: 45295 | I1044: Services | J1044: Opportunity | K1044: 5 | L1044: Initial contact | M1044: 2 | N1044: 785 | O1044: 0.6 | P1044: 45343
A1045: Youspan | B1045: France | C1045: 48.864716 | D1045: 2.349014 | E1045: Entertainment & Media & Hospitality | F1045: Small (11-200) | G1045: Laura Thompson | H1045: 45299 | I1045: Services | J1045: Opportunity | K1045: 5 | L1045: Initial contact | M1045: 2 | N1045: 1380 | O1045: 0.3 | P1045: 45641
A1046: Realfire | B1046: Spain | C1046: 40.416775 | D1046: -3.70379 | E1046: Retail & Distribution | F1046: Small (11-200) | G1046: Jessica Martinez | H1046: 45415 | I1046: Services | J1046: Opportunity | K1046: 5 | L1046: Initial contact | M1046: 2 | N1046: 1885 | O1046: 0.7 | P1046: 45580
A1047: Quinu | B1047: Switzerland | C1047: 46.204391 | D1047: 6.143158 | E1047: IT & IT Services | F1047: Small (11-200) | G1047: Laura Thompson | H1047: 45320 | I1047: Services | J1047: Opportunity | K1047: 5 | L1047: Initial contact | M1047: 2 | N1047: 1320 | O1047: 0.7 | P1047: 45342
A1048: Devpulse | B1048: Portugal | C1048: 38.736946 | D1048: -9.142685 | E1048: Transportation & Logistics | F1048: Small (11-200) | G1048: Michael Brown | H1048: 45354 | I1048: Services | J1048: Opportunity | K1048: 5 | L1048: Initial contact | M1048: 2 | N1048: 683 | O1048: 1 | P1048: 45625
A1049: Skiptube | B1049: Switzerland | C1049: 46.204391 | D1049: 6.143158 | E1049: Transportation & Logistics | F1049: Small (11-200) | G1049: Laura Thompson | H1049: 45375 | I1049: Services | J1049: Opportunity | K1049: 5 | L1049: Initial contact | M1049: 2 | N1049: 909 | O1049: 0.4 | P1049: 45411
A1050: Skyndu | B1050: Germany | C1050: 52.520008 | D1050: 13.404954 | E1050: Banking & Finance | F1050: Small (11-200) | G1050: Jessica Martinez | H1050: 45315 | I1050: SAAS | J1050: Opportunity | K1050: 5 | L1050: Initial contact | M1050: 2 | N1050: 673 | O1050: 0.6 | P1050: 45647
A1051: Steuber-Lowe | B1051: Belgium | C1051: 51.260197 | D1051: 4.402771 | E1051: Government Administration & Healthcare | F1051: Small (11-200) | G1051: John Smith | H1051: 45388 | I1051: Custom solution | J1051: Opportunity | K1051: 5 | L1051: Initial contact | M1051: 2 | N1051: 1498 | O1051: 0.6 | P1051: 45496
... A1906: Wunsch Group | B1906: Germany | C1906: 52.520008 | D1906: 13.404954 | E1906: Banking & Finance | F1906: Enterprise (1001+) | G1906: Michael Brown | H1906: 45332 | I1906: Custom solution | J1906: Opportunity | K1906: 5 | L1906: Won | M1906: 5 | N1906: 5433 | O1906: 0.3 | P1906: 45414
...

Sheet EDA_Pipeline
B2: EDA — Pipeline flow
B3: Exploratory analysis of the cleaned CRM dataset, providing the quantitative foundation for dashboard design and KPI definition.
B5: 1 · Baseline
B6: Metric | C6: Value
B7: Total leads | C7: =COUNTA(Cleaned_Data[Status]) -> 3000
B8: Converted leads | C8: =COUNTIF(Cleaned_Data[Status],"Customer")+COUNTIF(Cleaned_Data[Status],"Churned Customer") -> 348 | D8: Customer + Churned Customer
B9: Won (stage) | C9: =COUNTIFS(Cleaned_Data[Status],"Opportunity",Cleaned_Data[Stage],"Won") -> 83
B10: Lost | C10: =COUNTIFS(Cleaned_Data[Status],"Opportunity",Cleaned_Data[Stage],"Lost") -> 61
B11: Decided deals (n) | C11: =C8+C9+C10 -> 492 | D11: Sample size behind every Win Rate
B12: Win Rate — benchmark | C12: =(C8+C9)/C11 -> 0.87601626 | D12: Benchmark for every segment comparison on EDA_Segments
B13: Conversion Rate | C13: =C8/C7 -> 0.116
B14: Churn Rate | C14: =COUNTIF(Cleaned_Data[Status],"Churned Customer")/C8 -> 0.50862069 | D14: Measured inside the converted base only
B15: Disqualification Rate | C15: =COUNTIF(Cleaned_Data[Status],"Disqualified")/C7 -> 0.059
B16: Open pipeline value | C16: =SUMIFS(Cleaned_Data[Deal Value],Cleaned_Data[Status],"<>Disqualified",Cleaned_Data[Status],"<>Customer",Cleaned_Data[Status],"<>Churned Customer")-SUMIFS(Cleaned_Data[Deal Value],Cleaned_Data[Status],"Opportunity",Cleaned_Data[Stage],"Lost") -> 6629409 | D16: Excludes Disqualified, Lost and anything already closed
B17: Realized revenue | C17: =SUMIFS(Cleaned_Data[Deal Value],Cleaned_Data[Status],"Customer") -> 425393 | D17: Still-active customers only; churned value shows up in Churn Rate
B18: Avg deal value | C18: =AVERAGE(Cleaned_Data[Deal Value]) -> 2758.3783
B19: Median deal value | C19: =MEDIAN(Cleaned_Data[Deal Value]) -> 1430 | D19: Right-skewed — quote the median, not the mean
B20: Min decided deals (n) | C20: 30
B22: Win Rate measures sales execution after an opportunity reaches a final outcome. Open opportunities are excluded from the denominator.
B24: 2 · Status distribution
B25: Status | C25: Seq | D25: Leads | E25: % of total
B26: New | C26: 1 | D26: =COUNTIF(Cleaned_Data[Status],$B26) -> 513 | E26: =D26/$C$7 -> 0.171
B27: Qualified | C27: 2 | D27: =COUNTIF(Cleaned_Data[Status],$B27) -> 567 | E27: =D27/$C$7 -> 0.189
B28: Sales Accepted | C28: 3 | D28: =COUNTIF(Cleaned_Data[Status],$B28) -> 528 | E28: =D28/$C$7 -> 0.176
B29: Opportunity | C29: 4 | D29: =COUNTIF(Cleaned_Data[Status],$B29) -> 867 | E29: =D29/$C$7 -> 0.289
B30: Customer | C30: 5 | D30: =COUNTIF(Cleaned_Data[Status],$B30) -> 171 | E30: =D30/$C$7 -> 0.057
B31: Churned Customer | C31: 6 | D31: =COUNTIF(Cleaned_Data[Status],$B31) -> 177 | E31: =D31/$C$7 -> 0.059
B32: Disqualified | C32: — | D32: =COUNTIF(Cleaned_Data[Status],$B32) -> 177 | E32: =D32/$C$7 -> 0.059
B33: Total | D33: =SUM(D26:D32) -> 3000
B35: This distribution reflects the current CRM snapshot rather than progression through the sales pipeline. Opportunity is the dominant active status (28.9%), while only 11.6% of records have reached a converted outcome (Customer or Churned Customer).
B38: 3 · Open-stage backlog
B40: Status | C40: Opportunity
B42: Stage | C42: Leads | D42: % of open
B43: Opened | C43: 65 | D43: 0.074971165
B44: Initial contact | C44: 298 | D44: 0.34371396
B45: Nurturing | C45: 220 | D45: 0.25374856
B46: Proposal sent | C46: 140 | D46: 0.16147636
B47: Won | C47: 83 | D47: 0.095732411
B48: Lost | C48: 61 | D48: 0.070357555
B49: Grand Total | C49: 867 | D49: 1
...

Sheet EDA_Segments
B2: EDA — Segment performance
B3: Win Rate is evaluated against the overall benchmark (87.6%). Benchmark deviation is reported only for segments with at least 30 decided deals to reduce volatility from small samples.
B4: Conversion, Win Rate and Churn Rate are calculated with worksheet formulas because they depend on business rules rather than simple aggregation.
B6: 1 · Country
B7: Segment | C7: Leads | D7: Open pipeline | E7: Converted | F7: Won | G7: Lost | H7: n | I7: Conv. rate | J7: Win rate | K7: Δ vs bench | L7: Churn rate
B8: Italy | C8: =COUNTIF(Cleaned_Data[Country],$B8) -> 620 | D8: =SUMIFS(Cleaned_Data[Deal Value],Cleaned_Data[Country],$B8,Cleaned_Data[Status],"<>Disqualified",Cleaned_Data[Status],"<>Customer",Cleaned_Data[Status],"<>Churned Customer")-SUMIFS(Cleaned_Data[Deal Value],Cleaned_Data[Country],$B8,Cleaned_Data[Status],"Opportunity",Cleaned_Data[Stage],"Lost") -> 1342848 | E8: =COUNTIFS(Cleaned_Data[Country],$B8,Cleaned_Data[Status],"Customer")+COUNTIFS(Cleaned_Data[Country],$B8,Cleaned_Data[Status],"Churned Customer") -> 80 | F8: =COUNTIFS(Cleaned_Data[Country],$B8,Cleaned_Data[Status],"Opportunity",Cleaned_Data[Stage],"Won") -> 18 | G8: =COUNTIFS(Cleaned_Data[Country],$B8,Cleaned_Data[Status],"Opportunity",Cleaned_Data[Stage],"Lost") -> 15 | H8: =E8+F8+G8 -> 113 | I8: =E8/C8 -> 0.12903226 | J8: =IFERROR((E8+F8)/H8,"") -> 0.86725664 | K8: =IF(H8>=EDA_Pipeline!$C$20,J8-EDA_Pipeline!$C$12,"") -> -0.008759623 | L8: =IFERROR(COUNTIFS(Cleaned_Data[Country],$B8,Cleaned_Data[Status],"Churned Customer")/E8,"") -> 0.5375
B9: France | C9: =COUNTIF(Cleaned_Data[Country],$B9) -> 422 | D9: =SUMIFS(Cleaned_Data[Deal Value],Cleaned_Data[Country],$B9,Cleaned_Data[Status],"<>Disqualified",Cleaned_Data[Status],"<>Customer",Cleaned_Data[Status],"<>Churned Customer")-SUMIFS(Cleaned_Data[Deal Value],Cleaned_Data[Country],$B9,Cleaned_Data[Status],"Opportunity",Cleaned_Data[Stage],"Lost") -> 1001594 | E9: =COUNTIFS(Cleaned_Data[Country],$B9,Cleaned_Data[Status],"Customer")+COUNTIFS(Cleaned_Data[Country],$B9,Cleaned_Data[Status],"Churned Customer") -> 42 | F9: =COUNTIFS(Cleaned_Data[Country],$B9,Cleaned_Data[Status],"Opportunity",Cleaned_Data[Stage],"Won") -> 12 | G9: =COUNTIFS(Cleaned_Data[Country],$B9,Cleaned_Data[Status],"Opportunity",Cleaned_Data[Stage],"Lost") -> 9 | H9: =E9+F9+G9 -> 63 | I9: =E9/C9 -> 0.099526066 | J9: =IFERROR((E9+F9)/H9,"") -> 0.85714286 | K9: =IF(H9>=EDA_Pipeline!$C$20,J9-EDA_Pipeline!$C$12,"") -> -0.018873403 | L9: =IFERROR(COUNTIFS(Cleaned_Data[Country],$B9,Cleaned_Data[Status],"Churned Customer")/E9,"") -> 0.42857143
B10: Germany | C10: =COUNTIF(Cleaned_Data[Country],$B10) -> 420 | D10: =SUMIFS(Cleaned_Data[Deal Value],Cleaned_Data[Country],$B10,Cleaned_Data[Status],"<>Disqualified",Cleaned_Data[Status],"<>Customer",Cleaned_Data[Status],"<>Churned Customer")-SUMIFS(Cleaned_Data[Deal Value],Cleaned_Data[Country],$B10,Cleaned_Data[Status],"Opportunity",Cleaned_Data[Stage],"Lost") -> 1020372 | E10: =COUNTIFS(Cleaned_Data[Country],$B10,Cleaned_Data[Status],"Customer")+COUNTIFS(Cleaned_Data[Country],$B10,Cleaned_Data[Status],"Churned Customer") -> 40 | F10: =COUNTIFS(Cleaned_Data[Country],$B10,Cleaned_Data[Status],"Opportunity",Cleaned_Data[Stage],"Won") -> 13 | G10: =COUNTIFS(Cleaned_Data[Country],$B10,Cleaned_Data[Status],"Opportunity",Cleaned_Data[Stage],"Lost") -> 10 | H10: =E10+F10+G10 -> 63 | I10: =E10/C10 -> 0.095238095 | J10: =IFERROR((E10+F10)/H10,"") -> 0.84126984 | K10: =IF(H10>=EDA_Pipeline!$C$20,J10-EDA_Pipeline!$C$12,"") -> -0.034746419 | L10: =IFERROR(COUNTIFS(Cleaned_Data[Country],$B10,Cleaned_Data[Status],"Churned Customer")/E10,"") -> 0.575
B11: Switzerland | C11: =COUNTIF(Cleaned_Data[Country],$B11) -> 392 | D11: =SUMIFS(Cleaned_Data[Deal Value],Cleaned_Data[Country],$B11,Cleaned_Data[Status],"<>Disqualified",Cleaned_Data[Status],"<>Customer",Cleaned_Data[Status],"<>Churned Customer")-SUMIFS(Cleaned_Data[Deal Value],Cleaned_Data[Country],$B11,Cleaned_Data[Status],"Opportunity",Cleaned_Data[Stage],"Lost") -> 824885 | E11: =COUNTIFS(Cleaned_Data[Country],$B11,Cleaned_Data[Status],"Customer")+COUNTIFS(Cleaned_Data[Country],$B11,Cleaned_Data[Status],"Churned Customer") -> 38 | F11: =COUNTIFS(Cleaned_Data[Country],$B11,Cleaned_Data[Status],"Opportunity",Cleaned_Data[Stage],"Won") -> 9 | G11: =COUNTIFS(Cleaned_Data[Country],$B11,Cleaned_Data[Status],"Opportunity",Cleaned_Data[Stage],"Lost") -> 6 | H11: =E11+F11+G11 -> 53 | I11: =E11/C11 -> 0.096938776 | J11: =IFERROR((E11+F11)/H11,"") -> 0.88679245 | K11: =IF(H11>=EDA_Pipeline!$C$20,J11-EDA_Pipeline!$C$12,"") -> 0.010776193 | L11: =IFERROR(COUNTIFS(Cleaned_Data[Country],$B11,Cleaned_Data[Status],"Churned Customer")/E11,"") -> 0.60526316
B12: Portugal | C12: =COUNTIF(Cleaned_Data[Country],$B12) -> 371 | D12: =SUMIFS(Cleaned_Data[Deal Value],Cleaned_Data[Country],$B12,Cleaned_Data[Status],"<>Disqualified",Cleaned_Data[Status],"<>Customer",Cleaned_Data[Status],"<>Churned Customer")-SUMIFS(Cleaned_Data[Deal Value],Cleaned_Data[Country],$B12,Cleaned_Data[Status],"Opportunity",Cleaned_Data[Stage],"Lost") -> 748391 | E12: =COUNTIFS(Cleaned_Data[Country],$B12,Cleaned_Data[Status],"Customer")+COUNTIFS(Cleaned_Data[Country],$B12,Cleaned_Data[Status],"Churned Customer") -> 51 | F12: =COUNTIFS(Cleaned_Data[Country],$B12,Cleaned_Data[Status],"Opportunity",Cleaned_Data[Stage],"Won") -> 8 | G12: =COUNTIFS(Cleaned_Data[Country],$B12,Cleaned_Data[Status],"Opportunity",Cleaned_Data[Stage],"Lost") -> 9 | H12: =E12+F12+G12 -> 68 | I12: =E12/C12 -> 0.13746631 | J12: =IFERROR((E12+F12)/H12,"") -> 0.86764706 | K12: =IF(H12>=EDA_Pipeline!$C$20,J12-EDA_Pipeline!$C$12,"") -> -0.0083692013 | L12: =IFERROR(COUNTIFS(Cleaned_Data[Country],$B12,Cleaned_Data[Status],"Churned Customer")/E12,"") -> 0.45098039
B13: Belgium | C13: =COUNTIF(Cleaned_Data[Country],$B13) -> 207 | D13: =SUMIFS(Cleaned_Data[Deal Value],Cleaned_Data[Country],$B13,Cleaned_Data[Status],"<>Disqualified",Cleaned_Data[Status],"<>Customer",Cleaned_Data[Status],"<>Churned Customer")-SUMIFS(Cleaned_Data[Deal Value],Cleaned_Data[Country],$B13,Cleaned_Data[Status],"Opportunity",Cleaned_Data[Stage],"Lost") -> 434511 | E13: =COUNTIFS(Cleaned_Data[Country],$B13,Cleaned_Data[Status],"Customer")+COUNTIFS(Cleaned_Data[Country],$B13,Cleaned_Data[Status],"Churned Customer") -> 25 | F13: =COUNTIFS(Cleaned_Data[Country],$B13,Cleaned_Data[Status],"Opportunity",Cleaned_Data[Stage],"Won") -> 11 | G13: =COUNTIFS(Cleaned_Data[Country],$B13,Cleaned_Data[Status],"Opportunity",Cleaned_Data[Stage],"Lost") -> 4 | H13: =E13+F13+G13 -> 40 | I13: =E13/C13 -> 0.12077295 | J13: =IFERROR((E13+F13)/H13,"") -> 0.9 | K13: =IF(H13>=EDA_Pipeline!$C$20,J13-EDA_Pipeline!$C$12,"") -> 0.02398374 | L13: =IFERROR(COUNTIFS(Cleaned_Data[Country],$B13,Cleaned_Data[Status],"Churned Customer")/E13,"") -> 0.36
B14: Austria | C14: =COUNTIF(Cleaned_Data[Country],$B14) -> 199 | D14: =SUMIFS(Cleaned_Data[Deal Value],Cleaned_Data[Country],$B14,Cleaned_Data[Status],"<>Disqualified",Cleaned_Data[Status],"<>Customer",Cleaned_Data[Status],"<>Churned Customer")-SUMIFS(Cleaned_Data[Deal Value],Cleaned_Data[Country],$B14,Cleaned_Data[Status],"Opportunity",Cleaned_Data[Stage],"Lost") -> 390796 | E14: =COUNTIFS(Cleaned_Data[Country],$B14,Cleaned_Data[Status],"Customer")+COUNTIFS(Cleaned_Data[Country],$B14,Cleaned_Data[Status],"Churned Customer") -> 20 | F14: =COUNTIFS(Cleaned_Data[Country],$B14,Cleaned_Data[Status],"Opportunity",Cleaned_Data[Stage],"Won") -> 2 | G14: =COUNTIFS(Cleaned_Data[Country],$B14,Cleaned_Data[Status],"Opportunity",Cleaned_Data[Stage],"Lost") -> 3 | H14: =E14+F14+G14 -> 25 | I14: =E14/C14 -> 0.10050251 | J14: =IFERROR((E14+F14)/H14,"") -> 0.88 | K14: =IF(H14>=EDA_Pipeline!$C$20,J14-EDA_Pipeline!$C$12,"") | L14: =IFERROR(COUNTIFS(Cleaned_Data[Country],$B14,Cleaned_Data[Status],"Churned Customer")/E14,"") -> 0.45
B15: Spain | C15: =COUNTIF(Cleaned_Data[Country],$B15) -> 189 | D15: =SUMIFS(Cleaned_Data[Deal Value],Cleaned_Data[Country],$B15,Cleaned_Data[Status],"<>Disqualified",Cleaned_Data[Status],"<>Customer",Cleaned_Data[Status],"<>Churned Customer")-SUMIFS(Cleaned_Data[Deal Value],Cleaned_Data[Country],$B15,Cleaned_Data[Status],"Opportunity",Cleaned_Data[Stage],"Lost") -> 444761 | E15: =COUNTIFS(Cleaned_Data[Country],$B15,Cleaned_Data[Status],"Customer")+COUNTIFS(Cleaned_Data[Country],$B15,Cleaned_Data[Status],"Churned Customer") -> 25 | F15: =COUNTIFS(Cleaned_Data[Country],$B15,Cleaned_Data[Status],"Opportunity",Cleaned_Data[Stage],"Won") -> 5 | G15: =COUNTIFS(Cleaned_Data[Country],$B15,Cleaned_Data[Status],"Opportunity",Cleaned_Data[Stage],"Lost") -> 2 | H15: =E15+F15+G15 -> 32 | I15: =E15/C15 -> 0.13227513 | J15: =IFERROR((E15+F15)/H15,"") -> 0.9375 | K15: =IF(H15>=EDA_Pipeline!$C$20,J15-EDA_Pipeline!$C$12,"") -> 0.06148374 | L15: =IFERROR(COUNTIFS(Cleaned_Data[Country],$B15,Cleaned_Data[Status],"Churned Customer")/E15,"") -> 0.64
B16: Netherlands | C16: =COUNTIF(Cleaned_Data[Country],$B16) -> 180 | D16: =SUMIFS(Cleaned_Data[Deal Value],Cleaned_Data[Country],$B16,Cleaned_Data[Status],"<>Disqualified",Cleaned_Data[Status],"<>Customer",Cleaned_Data[Status],"<>Churned Customer")-SUMIFS(Cleaned_Data[Deal Value],Cleaned_Data[Country],$B16,Cleaned_Data[Status],"Opportunity",Cleaned_Data[Stage],"Lost") -> 421251 | E16: =COUNTIFS(Cleaned_Data[Country],$B16,Cleaned_Data[Status],"Customer")+COUNTIFS(Cleaned_Data[Country],$B16,Cleaned_Data[Status],"Churned Customer") -> 27 | F16: =COUNTIFS(Cleaned_Data[Country],$B16,Cleaned_Data[Status],"Opportunity",Cleaned_Data[Stage],"Won") -> 5 | G16: =COUNTIFS(Cleaned_Data[Country],$B16,Cleaned_Data[Status],"Opportunity",Cleaned_Data[Stage],"Lost") -> 3 | H16: =E16+F16+G16 -> 35 | I16: =E16/C16 -> 0.15 | J16: =IFERROR((E16+F16)/H16,"") -> 0.91428571 | K16: =IF(H16>=EDA_Pipeline!$C$20,J16-EDA_Pipeline!$C$12,"") -> 0.038269454 | L16: =IFERROR(COUNTIFS(Cleaned_Data[Country],$B16,Cleaned_Data[Status],"Churned Customer")/E16,"") -> 0.48148148
B18: 2 · Industry
B19: Segment | C19: Leads | D19: Open pipeline | E19: Converted | F19: Won | G19: Lost | H19: n | I19: Conv. rate | J19: Win rate | K19: Δ vs bench | L19: Churn rate
B20: Agriculture & Mining | C20: =COUNTIF(Cleaned_Data[Industry],$B20) -> 134 | D20: =SUMIFS(Cleaned_Data[Deal Value],Cleaned_Data[Industry],$B20,Cleaned_Data[Status],"<>Disqualified",Cleaned_Data[Status],"<>Customer",Cleaned_Data[Status],"<>Churned Customer")-SUMIFS(Cleaned_Data[Deal Value],Cleaned_Data[Industry],$B20,Cleaned_Data[Status],"Opportunity",Cleaned_Data[Stage],"Lost") -> 302341 | E20: =COUNTIFS(Cleaned_Data[Industry],$B20,Cleaned_Data[Status],"Customer")+COUNTIFS(Cleaned_Data[Industry],$B20,Cleaned_Data[Status],"Churned Customer") -> 18 | F20: =COUNTIFS(Cleaned_Data[Industry],$B20,Cleaned_Data[Status],"Opportunity",Cleaned_Data[Stage],"Won") -> 2 | G20: =COUNTIFS(Cleaned_Data[Industry],$B20,Cleaned_Data[Status],"Opportunity",Cleaned_Data[Stage],"Lost") -> 7 | H20: =E20+F20+G20 -> 27 | I20: =E20/C20 -> 0.13432836 | J20: =IFERROR((E20+F20)/H20,"") -> 0.74074074 | K20: =IF(H20>=EDA_Pipeline!$C$20,J20-EDA_Pipeline!$C$12,"") | L20: =IFERROR(COUNTIFS(Cleaned_Data[Industry],$B20,Cleaned_Data[Status],"Churned Customer")/E20,"") -> 0.61111111
B21: Banking & Finance | C21: =COUNTIF(Cleaned_Data[Industry],$B21) -> 404 | D21: =SUMIFS(Cleaned_Data[Deal Value],Cleaned_Data[Industry],$B21,Cleaned_Data[Status],"<>Disqualified",Cleaned_Data[Status],"<>Customer",Cleaned_Data[Status],"<>Churned Customer")-SUMIFS(Cleaned_Data[Deal Value],Cleaned_Data[Industry],$B21,Cleaned_Data[Status],"Opportunity",Cleaned_Data[Stage],"Lost") -> 835565 | E21: =COUNTIFS(Cleaned_Data[Industry],$B21,Cleaned_Data[Status],"Customer")+COUNTIFS(Cleaned_Data[Industry],$B21,Cleaned_Data[Status],"Churned Customer") -> 47 | F21: =COUNTIFS(Cleaned_Data[Industry],$B21,Cleaned_Data[Status],"Opportunity",Cleaned_Data[Stage],"Won") -> 15 | G21: =COUNTIFS(Cleaned_Data[Industry],$B21,Cleaned_Data[Status],"Opportunity",Cleaned_Data[Stage],"Lost") -> 6 | H21: =E21+F21+G21 -> 68 | I21: =E21/C21 -> 0.11633663 | J21: =IFERROR((E21+F21)/H21,"") -> 0.91176471 | K21: =IF(H21>=EDA_Pipeline!$C$20,J21-EDA_Pipeline!$C$12,"") -> 0.035748446 | L21: =IFERROR(COUNTIFS(Cleaned_Data[Industry],$B21,Cleaned_Data[Status],"Churned Customer")/E21,"") -> 0.55319149
B22: Construction & Engineering | C22: =COUNTIF(Cleaned_Data[Industry],$B22) -> 110 | D22: =SUMIFS(Cleaned_Data[Deal Value],Cleaned_Data[Industry],$B22,Cleaned_Data[Status],"<>Disqualified",Cleaned_Data[Status],"<>Customer",Cleaned_Data[Status],"<>Churned Customer")-SUMIFS(Cleaned_Data[Deal Value],Cleaned_Data[Industry],$B22,Cleaned_Data[Status],"Opportunity",Cleaned_Data[Stage],"Lost") -> 259108 | E22: =COUNTIFS(Cleaned_Data[Industry],$B22,Cleaned_Data[Status],"Customer")+COUNTIFS(Cleaned_Data[Industry],$B22,Cleaned_Data[Status],"Churned Customer") -> 11 | F22: =COUNTIFS(Cleaned_Data[Industry],$B22,Cleaned_Data[Status],"Opportunity",Cleaned_Data[Stage],"Won") -> 1 | G22: =COUNTIFS(Cleaned_Data[Industry],$B22,Cleaned_Data[Status],"Opportunity",Cleaned_Data[Stage],"Lost") -> 2 | H22: =E22+F22+G22 -> 14 | I22: =E22/C22 -> 0.1 | J22: =IFERROR((E22+F22)/H22,"") -> 0.85714286 | K22: =IF(H22>=EDA_Pipeline!$C$20,J22-EDA_Pipeline!$C$12,"") | L22: =IFERROR(COUNTIFS(Cleaned_Data[Industry],$B22,Cleaned_Data[Status],"Churned Customer")/E22,"") -> 0.63636364
B23: Education & Science | C23: =COUNTIF(Cleaned_Data[Industry],$B23) -> 140 | D23: =SUMIFS(Cleaned_Data[Deal Value],Cleaned_Data[Industry],$B23,Cleaned_Data[Status],"<>Disqualified",Cleaned_Data[Status],"<>Customer",Cleaned_Data[Status],"<>Churned Customer")-SUMIFS(Cleaned_Data[Deal Value],Cleaned_Data[Industry],$B23,Cleaned_Data[Status],"Opportunity",Cleaned_Data[Stage],"Lost") -> 256924 | E23: =COUNTIFS(Cleaned_Data[Industry],$B23,Cleaned_Data[Status],"Customer")+COUNTIFS(Cleaned_Data[Industry],$B23,Cleaned_Data[Status],"Churned Customer") -> 20 | F23: =COUNTIFS(Cleaned_Data[Industry],$B23,Cleaned_Data[Status],"Opportunity",Cleaned_Data[Stage],"Won") -> 1 | G23: =COUNTIFS(Cleaned_Data[Industry],$B23,Cleaned_Data[Status],"Opportunity",Cleaned_Data[Stage],"Lost") -> 0 | H23: =E23+F23+G23 -> 21 | I23: =E23/C23 -> 0.14285714 | J23: =IFERROR((E23+F23)/H23,"") -> 1 | K23: =IF(H23>=EDA_Pipeline!$C$20,J23-EDA_Pipeline!$C$12,"") | L23: =IFERROR(COUNTIFS(Cleaned_Data[Industry],$B23,Cleaned_Data[Status],"Churned Customer")/E23,"") -> 0.7
B24: Energy & Utilities | C24: =COUNTIF(Cleaned_Data[Industry],$B24) -> 127 | D24: =SUMIFS(Cleaned_Data[Deal Value],Cleaned_Data[Industry],$B24,Cleaned_Data[Status],"<>Disqualified",Cleaned_Data[Status],"<>Customer",Cleaned_Data[Status],"<>Churned Customer")-SUMIFS(Cleaned_Data[Deal Value],Cleaned_Data[Industry],$B24,Cleaned_Data[Status],"Opportunity",Cleaned_Data[Stage],"Lost") -> 280889 | E24: =COUNTIFS(Cleaned_Data[Industry],$B24,Cleaned_Data[Status],"Customer")+COUNTIFS(Cleaned_Data[Industry],$B24,Cleaned_Data[Status],"Churned Customer") -> 10 | F24: =COUNTIFS(Cleaned_Data[Industry],$B24,Cleaned_Data[Status],"Opportunity",Cleaned_Data[Stage],"Won") -> 2 | G24: =COUNTIFS(Cleaned_Data[Industry],$B24,Cleaned_Data[Status],"Opportunity",Cleaned_Data[Stage],"Lost") -> 4 | H24: =E24+F24+G24 -> 16 | I24: =E24/C24 -> 0.078740157 | J24: =IFERROR((E24+F24)/H24,"") -> 0.75 | K24: =IF(H24>=EDA_Pipeline!$C$20,J24-EDA_Pipeline!$C$12,"") | L24: =IFERROR(COUNTIFS(Cleaned_Data[Industry],$B24,Cleaned_Data[Status],"Churned Customer")/E24,"") -> 0.6
B25: Entertainment & Media & Hospitality | C25: =COUNTIF(Cleaned_Data[Industry],$B25) -> 122 | D25: =SUMIFS(Cleaned_Data[Deal Value],Cleaned_Data[Industry],$B25,Cleaned_Data[Status],"<>Disqualified",Cleaned_Data[Status],"<>Customer",Cleaned_Data[Status],"<>Churned Customer")-SUMIFS(Cleaned_Data[Deal Value],Cleaned_Data[Industry],$B25,Cleaned_Data[Status],"Opportunity",Cleaned_Data[Stage],"Lost") -> 288834 | E25: =COUNTIFS(Cleaned_Data[Industry],$B25,Cleaned_Data[Status],"Customer")+COUNTIFS(Cleaned_Data[Industry],$B25,Cleaned_Data[Status],"Churned Customer") -> 12 | F25: =COUNTIFS(Cleaned_Data[Industry],$B25,Cleaned_Data[Status],"Opportunity",Cleaned_Data[Stage],"Won") -> 7 | G25: =COUNTIFS(Cleaned_Data[Industry],$B25,Cleaned_Data[Status],"Opportunity",Cleaned_Data[Stage],"Lost") -> 5 | H25: =E25+F25+G25 -> 24 | I25: =E25/C25 -> 0.098360656 | J25: =IFERROR((E25+F25)/H25,"") -> 0.79166667 | K25: =IF(H25>=EDA_Pipeline!$C$20,J25-EDA_Pipeline!$C$12,"") | L25: =IFERROR(COUNTIFS(Cleaned_Data[Industry],$B25,Cleaned_Data[Status],"Churned Customer")/E25,"") -> 0.25
B26: Government Administration & Healthcare | C26: =COUNTIF(Cleaned_Data[Industry],$B26) -> 253 | D26: =SUMIFS(Cleaned_Data[Deal Value],Cleaned_Data[Industry],$B26,Cleaned_Data[Status],"<>Disqualified",Cleaned_Data[Status],"<>Customer",Cleaned_Data[Status],"<>Churned Customer")-SUMIFS(Cleaned_Data[Deal Value],Cleaned_Data[Industry],$B26,Cleaned_Data[Status],"Opportunity",Cleaned_Data[Stage],"Lost") -> 539896 | E26: =COUNTIFS(Cleaned_Data[Industry],$B26,Cleaned_Data[Status],"Customer")+COUNTIFS(Cleaned_Data[Industry],$B26,Cleaned_Data[Status],"Churned Customer") -> 32 | F26: =COUNTIFS(Cleaned_Data[Industry],$B26,Cleaned_Data[Status],"Opportunity",Cleaned_Data[Stage],"Won") -> 6 | G26: =COUNTIFS(Cleaned_Data[Industry],$B26,Cleaned_Data[Status],"Opportunity",Cleaned_Data[Stage],"Lost") -> 8 | H26: =E26+F26+G26 -> 46 | I26: =E26/C26 -> 0.12648221 | J26: =IFERROR((E26+F26)/H26,"") -> 0.82608696 | K26: =IF(H26>=EDA_Pipeline!$C$20,J26-EDA_Pipeline!$C$12,"") -> -0.049929304 | L26: =IFERROR(COUNTIFS(Cleaned_Data[Industry],$B26,Cleaned_Data[Status],"Churned Customer")/E26,"") -> 0.59375
B27: IT & IT Services | C27: =COUNTIF(Cleaned_Data[Industry],$B27) -> 387 | D27: =SUMIFS(Cleaned_Data[Deal Value],Cleaned_Data[Industry],$B27,Cleaned_Data[Status],"<>Disqualified",Cleaned_Data[Status],"<>Customer",Cleaned_Data[Status],"<>Churned Customer")-SUMIFS(Cleaned_Data[Deal Value],Cleaned_Data[Industry],$B27,Cleaned_Data[Status],"Opportunity",Cleaned_Data[Stage],"Lost") -> 918051 | E27: =COUNTIFS(Cleaned_Data[Industry],$B27,Cleaned_Data[Status],"Customer")+COUNTIFS(Cleaned_Data[Industry],$B27,Cleaned_Data[Status],"Churned Customer") -> 41 | F27: =COUNTIFS(Cleaned_Data[Industry],$B27,Cleaned_Data[Status],"Opportunity",Cleaned_Data[Stage],"Won") -> 17 | G27: =COUNTIFS(Cleaned_Data[Industry],$B27,Cleaned_Data[Status],"Opportunity",Cleaned_Data[Stage],"Lost") -> 4 | H27: =E27+F27+G27 -> 62 | I27: =E27/C27 -> 0.10594315 | J27: =IFERROR((E27+F27)/H27,"") -> 0.93548387 | K27: =IF(H27>=EDA_Pipeline!$C$20,J27-EDA_Pipeline!$C$12,"") -> 0.059467611 | L27: =IFERROR(COUNTIFS(Cleaned_Data[Industry],$B27,Cleaned_Data[Status],"Churned Customer")/E27,"") -> 0.43902439
B28: Manufacturing & Production | C28: =COUNTIF(Cleaned_Data[Industry],$B28) -> 131 | D28: =SUMIFS(Cleaned_Data[Deal Value],Cleaned_Data[Industry],$B28,Cleaned_Data[Status],"<>Disqualified",Cleaned_Data[Status],"<>Customer",Cleaned_Data[Status],"<>Churned Customer")-SUMIFS(Cleaned_Data[Deal Value],Cleaned_Data[Industry],$B28,Cleaned_Data[Status],"Opportunity",Cleaned_Data[Stage],"Lost") -> 298986 | E28: =COUNTIFS(Cleaned_Data[Industry],$B28,Cleaned_Data[Status],"Customer")+COUNTIFS(Cleaned_Data[Industry],$B28,Cleaned_Data[Status],"Churned Customer") -> 16 | F28: =COUNTIFS(Cleaned_Data[Industry],$B28,Cleaned_Data[Status],"Opportunity",Cleaned_Data[Stage],"Won") -> 1 | G28: =COUNTIFS(Cleaned_Data[Industry],$B28,Cleaned_Data[Status],"Opportunity",Cleaned_Data[Stage],"Lost") -> 1 | H28: =E28+F28+G28 -> 18 | I28: =E28/C28 -> 0.1221374 | J28: =IFERROR((E28+F28)/H28,"") -> 0.94444444 | K28: =IF(H28>=EDA_Pipeline!$C$20,J28-EDA_Pipeline!$C$12,"") | L28: =IFERROR(COUNTIFS(Cleaned_Data[Industry],$B28,Cleaned_Data[Status],"Churned Customer")/E28,"") -> 0.25
B29: Professional Services & Consulting | C29: =COUNTIF(Cleaned_Data[Industry],$B29) -> 232 | D29: =SUMIFS(Cleaned_Data[Deal Value],Cleaned_Data[Industry],$B29,Cleaned_Data[Status],"<>Disqualified",Cleaned_Data[Status],"<>Customer",Cleaned_Data[Status],"<>Churned Customer")-SUMIFS(Cleaned_Data[Deal Value],Cleaned_Data[Industry],$B29,Cleaned_Data[Status],"Opportunity",Cleaned_Data[Stage],"Lost") -> 457203 | E29: =COUNTIFS(Cleaned_Data[Industry],$B29,Cleaned_Data[Status],"Customer")+COUNTIFS(Cleaned_Data[Industry],$B29,Cleaned_Data[Status],"Churned Customer") -> 29 | F29: =COUNTIFS(Cleaned_Data[Industry],$B29,Cleaned_Data[Status],"Opportunity",Cleaned_Data[Stage],"Won") -> 7 | G29: =COUNTIFS(Cleaned_Data[Industry],$B29,Cleaned_Data[Status],"Opportunity",Cleaned_Data[Stage],"Lost") -> 5 | H29: =E29+F29+G29 -> 41 | I29: =E29/C29 -> 0.125 | J29: =IFERROR((E29+F29)/H29,"") -> 0.87804878 | K29: =IF(H29>=EDA_Pipeline!$C$20,J29-EDA_Pipeline!$C$12,"") -> 0.0020325203 | L29: =IFERROR(COUNTIFS(Cleaned_Data[Industry],$B29,Cleaned_Data[Status],"Churned Customer")/E29,"") -> 0.44827586
B30: Recreation & Sports | C30: =COUNTIF(Cleaned_Data[Industry],$B30) -> 121 | D30: =SUMIFS(Cleaned_Data[Deal Value],Cleaned_Data[Industry],$B30,Cleaned_Data[Status],"<>Disqualified",Cleaned_Data[Status],"<>Customer",Cleaned_Data[Status],"<>Churned Customer")-SUMIFS(Cleaned_Data[Deal Value],Cleaned_Data[Industry],$B30,Cleaned_Data[Status],"Opportunity",Cleaned_Data[Stage],"Lost") -> 325382 | E30: =COUNTIFS(Cleaned_Data[Industry],$B30,Cleaned_Data[Status],"Customer")+COUNTIFS(Cleaned_Data[Industry],$B30,Cleaned_Data[Status],"Churned Customer") -> 8 | F30: =COUNTIFS(Cleaned_Data[Industry],$B30,Cleaned_Data[Status],"Opportunity",Cleaned_Data[Stage],"Won") -> 2 | G30: =COUNTIFS(Cleaned_Data[Industry],$B30,Cleaned_Data[Status],"Opportunity",Cleaned_Data[Stage],"Lost") -> 4 | H30: =E30+F30+G30 -> 14 | I30: =E30/C30 -> 0.066115702 | J30: =IFERROR((E30+F30)/H30,"") -> 0.71428571 | K30: =IF(H30>=EDA_Pipeline!$C$20,J30-EDA_Pipeline!$C$12,"") | L30: =IFERROR(COUNTIFS(Cleaned_Data[Industry],$B30,Cleaned_Data[Status],"Churned Customer")/E30,"") -> 0.5
B31: Retail & Distribution | C31: =COUNTIF(Cleaned_Data[Industry],$B31) -> 144 | D31: =SUMIFS(Cleaned_Data[Deal Value],Cleaned_Data[Industry],$B31,Cleaned_Data[Status],"<>Disqualified",Cleaned_Data[Status],"<>Customer",Cleaned_Data[Status],"<>Churned Customer")-SUMIFS(Cleaned_Data[Deal Value],Cleaned_Data[Industry],$B31,Cleaned_Data[Status],"Opportunity",Cleaned_Data[Stage],"Lost") -> 303241 | E31: =COUNTIFS(Cleaned_Data[Industry],$B31,Cleaned_Data[Status],"Customer")+COUNTIFS(Cleaned_Data[Industry],$B31,Cleaned_Data[Status],"Churned Customer") -> 18 | F31: =COUNTIFS(Cleaned_Data[Industry],$B31,Cleaned_Data[Status],"Opportunity",Cleaned_Data[Stage],"Won") -> 2 | G31: =COUNTIFS(Cleaned_Data[Industry],$B31,Cleaned_Data[Status],"Opportunity",Cleaned_Data[Stage],"Lost") -> 3 | H31: =E31+F31+G31 -> 23 | I31: =E31/C31 -> 0.125 | J31: =IFERROR((E31+F31)/H31,"") -> 0.86956522 | K31: =IF(H31>=EDA_Pipeline!$C$20,J31-EDA_Pipeline!$C$12,"") | L31: =IFERROR(COUNTIFS(Cleaned_Data[Industry],$B31,Cleaned_Data[Status],"Churned Customer")/E31,"") -> 0.5
... B33: Transportation & Logistics | C33: =COUNTIF(Cleaned_Data[Industry],$B33) -> 528 | D33: =SUMIFS(Cleaned_Data[Deal Value],Cleaned_Data[Industry],$B33,Cleaned_Data[Status],"<>Disqualified",Cleaned_Data[Status],"<>Customer",Cleaned_Data[Status],"<>Churned Customer")-SUMIFS(Cleaned_Data[Deal Value],Cleaned_Data[Industry],$B33,Cleaned_Data[Status],"Opportunity",Cleaned_Data[Stage],"Lost") -> 1159324 | E33: =COUNTIFS(Cleaned_Data[Industry],$B33,Cleaned_Data[Status],"Customer")+COUNTIFS(Cleaned_Data[Industry],$B33,Cleaned_Data[Status],"Churned Customer") -> 68 | F33: =COUNTIFS(Cleaned_Data[Industry],$B33,Cleaned_Data[Status],"Opportunity",Cleaned_Data[Stage],"Won") -> 16 | G33: =COUNTIFS(Cleaned_Data[Industry],$B33,Cleaned_Data[Status],"Opportunity",Cleaned_Data[Stage],"Lost") -> 11 | H33: =E33+F33+G33 -> 95 | I33: =E33/C33 -> 0.12878788 | J33: =IFERROR((E33+F33)/H33,"") -> 0.88421053 | K33: =IF(H33>=EDA_Pipeline!$C$20,J33-EDA_Pipeline!$C$12,"") -> 0.0081942662 | L33: =IFERROR(COUNTIFS(Cleaned_Data[Industry],$B33,Cleaned_Data[Status],"Churned Customer")/E33,"") -> 0.47058824
B35: 3 · Product
B36: Segment | C36: Leads | D36: Open pipeline | E36: Converted | F36: Won | G36: Lost | H36: n | I36: Conv. rate | J36: Win rate | K36: Δ vs bench | L36: Churn rate
B37: SAAS | C37: =COUNTIF(Cleaned_Data[Product],$B37) -> 1295 | D37: =SUMIFS(Cleaned_Data[Deal Value],Cleaned_Data[Product],$B37,Cleaned_Data[Status],"<>Disqualified",Cleaned_Data[Status],"<>Customer",Cleaned_Data[Status],"<>Churned Customer")-SUMIFS(Cleaned_Data[Deal Value],Cleaned_Data[Product],$B37,Cleaned_Data[Status],"Opportunity",Cleaned_Data[Stage],"Lost") -> 2468307 | E37: =COUNTIFS(Cleaned_Data[Product],$B37,Cleaned_Data[Status],"Customer")+COUNTIFS(Cleaned_Data[Product],$B37,Cleaned_Data[Status],"Churned Customer") -> 156 | F37: =COUNTIFS(Cleaned_Data[Product],$B37,Cleaned_Data[Status],"Opportunity",Cleaned_Data[Stage],"Won") -> 44 | G37: =COUNTIFS(Cleaned_Data[Product],$B37,Cleaned_Data[Status],"Opportunity",Cleaned_Data[Stage],"Lost") -> 27 | H37: =E37+F37+G37 -> 227 | I37: =E37/C37 -> 0.12046332 | J37: =IFERROR((E37+F37)/H37,"") -> 0.88105727 | K37: =IF(H37>=EDA_Pipeline!$C$20,J37-EDA_Pipeline!$C$12,"") -> 0.0050410086 | L37: =IFERROR(COUNTIFS(Cleaned_Data[Product],$B37,Cleaned_Data[Status],"Churned Customer")/E37,"") -> 0.51923077
B38: Custom solution | C38: =COUNTIF(Cleaned_Data[Product],$B38) -> 558 | D38: =SUMIFS(Cleaned_Data[Deal Value],Cleaned_Data[Product],$B38,Cleaned_Data[Status],"<>Disqualified",Cleaned_Data[Status],"<>Customer",Cleaned_Data[Status],"<>Churned Customer")-SUMIFS(Cleaned_Data[Deal Value],Cleaned_Data[Product],$B38,Cleaned_Data[Status],"Opportunity",Cleaned_Data[Stage],"Lost") -> 1472834 | E38: =COUNTIFS(Cleaned_Data[Product],$B38,Cleaned_Data[Status],"Customer")+COUNTIFS(Cleaned_Data[Product],$B38,Cleaned_Data[Status],"Churned Customer") -> 64 | F38: =COUNTIFS(Cleaned_Data[Product],$B38,Cleaned_Data[Status],"Opportunity",Cleaned_Data[Stage],"Won") -> 15 | G38: =COUNTIFS(Cleaned_Data[Product],$B38,Cleaned_Data[Status],"Opportunity",Cleaned_Data[Stage],"Lost") -> 11 | H38: =E38+F38+G38 -> 90 | I38: =E38/C38 -> 0.11469534 | J38: =IFERROR((E38+F38)/H38,"") -> 0.87777778 | K38: =IF(H38>=EDA_Pipeline!$C$20,J38-EDA_Pipeline!$C$12,"") -> 0.0017615176 | L38: =IFERROR(COUNTIFS(Cleaned_Data[Product],$B38,Cleaned_Data[Status],"Churned Customer")/E38,"") -> 0.53125
B39: Services | C39: =COUNTIF(Cleaned_Data[Product],$B39) -> 1147 | D39: =SUMIFS(Cleaned_Data[Deal Value],Cleaned_Data[Product],$B39,Cleaned_Data[Status],"<>Disqualified",Cleaned_Data[Status],"<>Customer",Cleaned_Data[Status],"<>Churned Customer")-SUMIFS(Cleaned_Data[Deal Value],Cleaned_Data[Product],$B39,Cleaned_Data[Status],"Opportunity",Cleaned_Data[Stage],"Lost") -> 2688268 | E39: =COUNTIFS(Cleaned_Data[Product],$B39,Cleaned_Data[Status],"Customer")+COUNTIFS(Cleaned_Data[Product],$B39,Cleaned_Data[Status],"Churned Customer") -> 128 | F39: =COUNTIFS(Cleaned_Data[Product],$B39,Cleaned_Data[Status],"Opportunity",Cleaned_Data[Stage],"Won") -> 24 | G39: =COUNTIFS(Cleaned_Data[Product],$B39,Cleaned_Data[Status],"Opportunity",Cleaned_Data[Stage],"Lost") -> 23 | H39: =E39+F39+G39 -> 175 | I39: =E39/C39 -> 0.11159547 | J39: =IFERROR((E39+F39)/H39,"") -> 0.86857143 | K39: =IF(H39>=EDA_Pipeline!$C$20,J39-EDA_Pipeline!$C$12,"") -> -0.0074448316 | L39: =IFERROR(COUNTIFS(Cleaned_Data[Product],$B39,Cleaned_Data[Status],"Churned Customer")/E39,"") -> 0.484375
B41: 4 · Organization size
B42: Segment | C42: Leads | D42: Open pipeline | E42: Converted | F42: Won | G42: Lost | H42: n | I42: Conv. rate | J42: Win rate | K42: Δ vs bench | L42: Churn rate
B43: Micro (1-10) | C43: =COUNTIF(Cleaned_Data[Organization Size],$B43) -> 646 | D43: =SUMIFS(Cleaned_Data[Deal Value],Cleaned_Data[Organization Size],$B43,Cleaned_Data[Status],"<>Disqualified",Cleaned_Data[Status],"<>Customer",Cleaned_Data[Status],"<>Churned Customer")-SUMIFS(Cleaned_Data[Deal Value],Cleaned_Data[Organization Size],$B43,Cleaned_Data[Status],"Opportunity",Cleaned_Data[Stage],"Lost") -> 359653 | E43: =COUNTIFS(Cleaned_Data[Organization Size],$B43,Cleaned_Data[Status],"Customer")+COUNTIFS(Cleaned_Data[Organization Size],$B43,Cleaned_Data[Status],"Churned Customer") -> 79 | F43: =COUNTIFS(Cleaned_Data[Organization Size],$B43,Cleaned_Data[Status],"Opportunity",Cleaned_Data[Stage],"Won") -> 16 | G43: =COUNTIFS(Cleaned_Data[Organization Size],$B43,Cleaned_Data[Status],"Opportunity",Cleaned_Data[Stage],"Lost") -> 12 | H43: =E43+F43+G43 -> 107 | I43: =E43/C43 -> 0.12229102 | J43: =IFERROR((E43+F43)/H43,"") -> 0.88785047 | K43: =IF(H43>=EDA_Pipeline!$C$20,J43-EDA_Pipeline!$C$12,"") -> 0.011834207 | L43: =IFERROR(COUNTIFS(Cleaned_Data[Organization Size],$B43,Cleaned_Data[Status],"Churned Customer")/E43,"") -> 0.51898734
B44: Small (11-200) | C44: =COUNTIF(Cleaned_Data[Organization Size],$B44) -> 949 | D44: =SUMIFS(Cleaned_Data[Deal Value],Cleaned_Data[Organization Size],$B44,Cleaned_Data[Status],"<>Disqualified",Cleaned_Data[Status],"<>Customer",Cleaned_Data[Status],"<>Churned Customer")-SUMIFS(Cleaned_Data[Deal Value],Cleaned_Data[Organization Size],$B44,Cleaned_Data[Status],"Opportunity",Cleaned_Data[Stage],"Lost") -> 830772 | E44: =COUNTIFS(Cleaned_Data[Organization Size],$B44,Cleaned_Data[Status],"Customer")+COUNTIFS(Cleaned_Data[Organization Size],$B44,Cleaned_Data[Status],"Churned Customer") -> 112 | F44: =COUNTIFS(Cleaned_Data[Organization Size],$B44,Cleaned_Data[Status],"Opportunity",Cleaned_Data[Stage],"Won") -> 34 | G44: =COUNTIFS(Cleaned_Data[Organization Size],$B44,Cleaned_Data[Status],"Opportunity",Cleaned_Data[Stage],"Lost") -> 20 | H44: =E44+F44+G44 -> 166 | I44: =E44/C44 -> 0.11801897 | J44: =IFERROR((E44+F44)/H44,"") -> 0.87951807 | K44: =IF(H44>=EDA_Pipeline!$C$20,J44-EDA_Pipeline!$C$12,"") -> 0.0035018121 | L44: =IFERROR(COUNTIFS(Cleaned_Data[Organization Size],$B44,Cleaned_Data[Status],"Churned Customer")/E44,"") -> 0.47321429
B45: Medium (201-500) | C45: =COUNTIF(Cleaned_Data[Organization Size],$B45) -> 1272 | D45: =SUMIFS(Cleaned_Data[Deal Value],Cleaned_Data[Organization Size],$B45,Cleaned_Data[Status],"<>Disqualified",Cleaned_Data[Status],"<>Customer",Cleaned_Data[Status],"<>Churned Customer")-SUMIFS(Cleaned_Data[Deal Value],Cleaned_Data[Organization Size],$B45,Cleaned_Data[Status],"Opportunity",Cleaned_Data[Stage],"Lost") -> 4216862 | E45: =COUNTIFS(Cleaned_Data[Organization Size],$B45,Cleaned_Data[Status],"Customer")+COUNTIFS(Cleaned_Data[Organization Size],$B45,Cleaned_Data[Status],"Churned Customer") -> 138 | F45: =COUNTIFS(Cleaned_Data[Organization Size],$B45,Cleaned_Data[Status],"Opportunity",Cleaned_Data[Stage],"Won") -> 30 | G45: =COUNTIFS(Cleaned_Data[Organization Size],$B45,Cleaned_Data[Status],"Opportunity",Cleaned_Data[Stage],"Lost") -> 26 | H45: =E45+F45+G45 -> 194 | I45: =E45/C45 -> 0.10849057 | J45: =IFERROR((E45+F45)/H45,"") -> 0.86597938 | K45: =IF(H45>=EDA_Pipeline!$C$20,J45-EDA_Pipeline!$C$12,"") -> -0.010036879 | L45: =IFERROR(COUNTIFS(Cleaned_Data[Organization Size],$B45,Cleaned_Data[Status],"Churned Customer")/E45,"") -> 0.51449275
B46: Large (501-1000) | C46: =COUNTIF(Cleaned_Data[Organization Size],$B46) -> 67 | D46: =SUMIFS(Cleaned_Data[Deal Value],Cleaned_Data[Organization Size],$B46,Cleaned_Data[Status],"<>Disqualified",Cleaned_Data[Status],"<>Customer",Cleaned_Data[Status],"<>Churned Customer")-SUMIFS(Cleaned_Data[Deal Value],Cleaned_Data[Organization Size],$B46,Cleaned_Data[Status],"Opportunity",Cleaned_Data[Stage],"Lost") -> 636326 | E46: =COUNTIFS(Cleaned_Data[Organization Size],$B46,Cleaned_Data[Status],"Customer")+COUNTIFS(Cleaned_Data[Organization Size],$B46,Cleaned_Data[Status],"Churned Customer") -> 8 | F46: =COUNTIFS(Cleaned_Data[Organization Size],$B46,Cleaned_Data[Status],"Opportunity",Cleaned_Data[Stage],"Won") -> 1 | G46: =COUNTIFS(Cleaned_Data[Organization Size],$B46,Cleaned_Data[Status],"Opportunity",Cleaned_Data[Stage],"Lost") -> 1 | H46: =E46+F46+G46 -> 10 | I46: =E46/C46 -> 0.11940299 | J46: =IFERROR((E46+F46)/H46,"") -> 0.9 | K46: =IF(H46>=EDA_Pipeline!$C$20,J46-EDA_Pipeline!$C$12,"") | L46: =IFERROR(COUNTIFS(Cleaned_Data[Organization Size],$B46,Cleaned_Data[Status],"Churned Customer")/E46,"") -> 0.75
...

Sheet KPI_Planning
B2: KPI planning
B3: Current values are validated against the cleaned dataset to ensure consistency before implementation in Power BI. Throughout this project, a lead is treated as converted once it reaches Customer or Churned Customer status.
B5: # | C5: KPI | D5: Business definition | E5: Excel check | F5: Power BI measure
B6: 1 | C6: Open Pipeline Value | D6: Deal Value of leads still open. Excludes Disqualified, Lost, and anything already converted. | E6: =EDA_Pipeline!$C$16 -> 6629409 | F6: [Open Pipeline Value]
B7: 2 | C7: Realized Revenue | D7: Deal Value of leads that converted and are still customers. Value lost to churn is reported by Churn Rate. | E7: =EDA_Pipeline!$C$17 -> 425393 | F7: [Realized Revenue]
B8: 3 | C8: Conversion Rate | D8: (Customer + Churned Customer) / Total Leads — a lead that converted then churned still converted. | E8: =EDA_Pipeline!$C$13 -> 0.116 | F8: [Conversion Rate] = DIVIDE([Converted Leads],[Total Leads])
B9: 4 | C9: Win Rate | D9: (Converted + Won) / (Converted + Won + Lost). Compared across segments only at n ≥ 30. | E9: =EDA_Pipeline!$C$12 -> 0.87601626 | F9: [Win Rate] — use [Win Rate (reliable)] wherever segments are ranked
B10: 5 | C10: Churn Rate | D10: Churned Customer / (Customer + Churned Customer) — attrition inside the converted base only. | E10: =EDA_Pipeline!$C$14 -> 0.50862069 | F10: [Churn Rate]
B11: 6 | C11: Disqualification Rate | D11: Disqualified / Total Leads. Separate from Win Rate because it reflects lead qualification, not sales execution. | E11: =EDA_Pipeline!$C$15 -> 0.059 | F11: [Disqualification Rate]
